Workbook
Name _.TableData._: #REF!
Name __MAIN__: CHEMICAL!#REF!
Name __MAIN__: #REF!
Name __QrHeader__: CHEMICAL!#REF!
Name __QrHeader__: [1]BTB!#REF!
Name __ZQ__: #REF!

Sheet GUDANG BESAR
B1: STOCK CHEMICAL
B3: GUDANG BESAR PER AGUSTUS 2025 | T3: 29764.323
J4: 0.11 | K4: 1.1 | T4: 29764.223 | U4: 0.1
A5: NO | B5: KETERANGAN | C5: NAMA BARANG | D5: SAT | E5: SALDO AWAL | F5: MUTASI MASUK | G5: MUTASI KELUAR | H5: FISIK | I5: HARGA DPP | J5: PPN | K5: HARGA+PPN | L5: JUMLAH FISIK | M5: JUMLAH SALDO AWAL + PPN | N5: JUMLAH MASUK + PPN | O5: JUMLAH KELUAR + PPN | P5: JUMLAH FISIK+ PPN | Q5: SELISIH | R5: CROSSCEK | S5: b | T5: OUT | U5: keterangan
A6: 1 | B6: BOILER | C6: CHEMPOWER - 1400 | D6: KG | E6: 180 | F6: 240 | G6: 240 | H6: 180 | I6: 24000 | J6: 2640 | K6: 26640 | L6: 4320000 | M6: 4795200 | N6: 6393600 | O6: 6393600 | P6: 4795200 | Q6: 240 | R6: 0 | S6: 180 | T6: 240 | U6: BOILER | V6: Boiler (13) / ON PROSES / MEMBERSIHKAN ZAT KAPUR | X6: #REF! | Y6: #REF!
A7: 2 | B7: BOILER | C7: CHEMPOWER - 2002 | D7: KG | E7: 180 | F7: 240 | G7: 240 | H7: 180 | I7: 23000 | J7: 2530 | K7: 25530 | L7: 4140000 | M7: 4595400 | N7: 6127200 | O7: 6127200 | P7: 4595400 | Q7: 240 | R7: 0 | S7: 180 | T7: 240 | U7: BOILER | V7: Boiler (13) / ON PROSES / MEMBERSIHKAN ZAT KAPUR | X7: #REF! | Y7: #REF!
A8: 3 | B8: BOILER | C8: GARAM KROGUS | D8: KG | E8: 2700 | F8: 0 | G8: 900 | H8: 1800 | I8: 1500 | K8: 1500 | L8: 2700000 | M8: 4050000 | N8: 0 | O8: 1350000 | P8: 2700000 | Q8: 900 | R8: 0 | S8: 1800 | T8: 900 | U8: BOILER | V8: Boiler (13) / ON PROSES / MEMBERSIHKAN ZAT KAPUR | X8: #REF! | Y8: #REF!
E9: 3060 | F9: 480 | G9: 1380 | H9: 2160 | L9: 11160000 | M9: 13440600 | N9: 12520800 | O9: 13870800 | P9: 12090600 | X9: #REF!
X10: #REF!
A11: 1 | B11: CHEM.PRINT | C11: LEM GML PK (LEM BLANKET) | D11: KG | E11: 150 | F11: 0 | G11: 10 | H11: 140 | I11: 115000 | J11: 12650 | K11: 127650 | L11: 16100000 | M11: 19147500 | N11: 0 | O11: 1276500 | P11: 17871000 | Q11: 10 | R11: 0 | S11: 140 | T11: 10 | U11: CHEMICAL PRINTING | V11: RFP / ON PROSES PRINTING | X11: #REF! | Y11: #REF!
A12: 2 | B12: CHEM.PRINT | C12: RENOGENT | D12: LITER | E12: 200 | F12: 0 | G12: 0 | H12: 200 | I12: 36000 | J12: 3960 | K12: 39960 | L12: 7200000 | M12: 7992000 | N12: 0 | O12: 0 | P12: 7992000 | Q12: 0 | R12: 0 | S12: 200 | T12: 0 | U12: CHEMICAL PRINTING | V12: STRIPPING FLAT (PRINTING) | X12: #REF! | Y12: #REF!
A13: 3 | B13: CHEM.PRINT | C13: THERMACOAT RESIN TO 90 | D13: KG | E13: 38 | F13: 0 | G13: 10 | H13: 30 | I13: 201876 | J13: 22206.36 | K13: 224082.36 | L13: 6056280 | M13: 8515129.7 | N13: 0 | O13: 2240823.6 | P13: 6722470.8 | Q13: 8 | R13: -2 | S13: 28 | T13: 10 | U13: CHEMICAL PRINTING | V13: RFP / ON PROSES DASAR LEM BLANKET | X13: #REF! | Y13: #REF!
A14: 4 | B14: CHEM.DYEING | C14: INNOTECH 260 (SUPER CLEAN) | D14: KG | E14: 0 | F14: 25 | G14: 25 | H14: 0 | I14: 57500 | J14: 6325 | K14: 63825 | L14: 0 | M14: 0 | N14: 1595625 | O14: 1595625 | P14: 0 | Q14: 25 | R14: 0 | S14: 0 | T14: 25 | U14: CHEMICAL PRINTING | V14: RFP / ON PROSES DASAR LEM BLANKET | X14: #REF! | Y14: #REF!
E15: 388 | F15: 25 | G15: 45 | H15: 370 | L15: 29356280 | M15: 35654630 | N15: 1595625 | O15: 5112948.6 | P15: 32585471 | X15: #REF!
X16: #REF!
A17: 1 | B17: CK | C17: ANTI UV - RUCO SHIELD RAY 500 | D17: KG | E17: 27 | F17: 0 | G17: 0 | H17: 27 | I17: 573981 | J17: 63137.91 | K17: 637118.91 | L17: 15497487 | M17: 17202211 | N17: 0 | O17: 0 | P17: 17202211 | Q17: 0 | R17: 0 | S17: 27 | T17: 0 | U17: CK | V17: ON PROSES | X17: #REF!
A18: 2 | B18: CK | C18: ANTISTATIK SZ - 52 | D18: KG | E18: 100 | F18: 0 | G18: 0 | H18: 100 | I18: 32510 | J18: 3576.1 | K18: 36086.1 | L18: 3251000 | M18: 3608610 | N18: 0 | O18: 0 | P18: 3608610 | Q18: 0 | R18: 0 | S18: 100 | T18: 0 | U18: CK | V18: RFP (CLP LORENG) / RFP (BLEACHING, KAIN TERTENTU) | X18: #REF!
A19: 3 | B19: CK | C19: BINDER 660 N | D19: KG | E19: 0 | F19: 0 | G19: 0 | H19: 0 | I19: 26262.5 | J19: 2888.875 | K19: 29151.375 | L19: 0 | M19: 0 | N19: 0 | O19: 0 | P19: 0 | Q19: 0 | R19: 0 | S19: 0 | T19: 0 | U19: CK | V19: ON PROSES | X19: #REF! | Y19: #REF!
A20: 4 | B20: CK | C20: BINDER FN (HARD BINDER) | D20: KG | E20: 588 | F20: 0 | G20: 0 | H20: 588 | I20: 25590.1 | J20: 2814.911 | K20: 28405.011 | L20: 15046979 | M20: 16702146 | N20: 0 | O20: 0 | P20: 16702146 | Q20: 0 | R20: 0 | S20: 588 | T20: 0 | U20: CK | V20: ON PROSES | X20: #REF!
A21: 5 | B21: CK | C21: BINDER SOFT TF - T 320 S | D21: KG | E21: 640 | F21: 0 | G21: 0 | H21: 640 | I21: 18076 | J21: 1988.36 | K21: 20064.36 | L21: 11568640 | M21: 12841190 | N21: 0 | O21: 0 | P21: 12841190 | Q21: 0 | R21: 0 | S21: 640 | T21: 0 | U21: CK | V21: ON PROSES | X21: #REF!
A22: 6 | B22: CK | C22: CITRIC ACID MONOHYDRATE | D22: KG | E22: 553 | F22: 0 | G22: 36.5 | H22: 517 | I22: 12250 | J22: 1347.5 | K22: 13597.5 | L22: 6333250 | M22: 7519417.5 | N22: 0 | O22: 496308.75 | P22: 7029907.5 | Q22: 36 | R22: -0.5 | S22: 516.5 | T22: 36.5 | U22: CK | V22: ON PROSES | X22: #REF! | Y22: #REF!
A23: 7 | B23: CK | C23: GLISERIN EX ECOCEROL | D23: KG | E23: 65 | F23: 0 | G23: 0 | H23: 65 | I23: 14500 | J23: 1595 | K23: 16095 | L23: 942500 | M23: 1046175 | N23: 0 | O23: 0 | P23: 1046175 | Q23: 0 | R23: 0 | S23: 65 | T23: 0 | U23: CK | V23: ON PROSES | X23: #REF!
A24: 8 | B24: CK | C24: LEOPRINT 700 ( SYNTETIC THICKENER ) | D24: KG | E24: 2700 | F24: 3180 | G24: 5340 | H24: 540 | I24: 23590.51 | J24: 2594.9561 | K24: 26185.466 | L24: 12738875 | M24: 70522464 | N24: 83269782 | O24: 1.3983039e+08 | P24: 14140152 | Q24: 5340 | R24: 0 | S24: 540 | T24: 5340 | U24: CK | V24: RFP (CLP LORENG) / RFP (BLEACHING, KAIN TERTENTU) | X24: #REF! | Y24: #REF!
A25: 9 | B25: CK | C25: PRINSOFT WKP | D25: KG | E25: 60 | F25: 0 | G25: 0 | H25: 60 | I25: 74315 | J25: 8174.65 | K25: 82489.65 | L25: 4458900 | M25: 4949379 | N25: 0 | O25: 0 | P25: 4949379 | Q25: 0 | R25: 0 | S25: 60 | T25: 0 | U25: CK | V25: ON PROSES | X25: #REF!
A26: 10 | B26: CK | C26: RUCO BINDER 1880 | D26: KG | E26: 347 | F26: 200 | G26: 197 | H26: 350 | I26: 17787 | J26: 1956.57 | K26: 19743.57 | L26: 6225450 | M26: 6910335 | N26: 3948714 | O26: 3889483.3 | P26: 6910249.5 | Q26: 197 | R26: 0 | S26: 350 | T26: 197 | U26: CK | V26: ON PROSES | X26: #REF! | Y26: #REF!
A27: 11 | B27: CK | C27: SODIUM HEXA METHA POSPHAT POWDER (SHMP) | D27: KG | E27: 439 | F27: 0 | G27: 18 | H27: 421 | I27: 15500 | J27: 1705 | K27: 17205 | L27: 6525500 | M27: 7552995 | N27: 0 | O27: 309690 | P27: 7243305 | Q27: 18 | R27: 0 | S27: 421 | T27: 18 | U27: CK | V27: ON PROSES | X27: #REF! | Y27: #REF!
A28: 12 | B28: CK | C28: STARSIN M80 ( FIXING AGENT ) | D28: KG | E28: 99 | F28: 0 | G28: 0 | H28: 99 | I28: 41548 | J28: 4570.28 | K28: 46118.28 | L28: 4113252 | M28: 4565709.7 | N28: 0 | O28: 0 | P28: 4565709.7 | Q28: 0 | R28: 0 | S28: 99 | T28: 0 | U28: CK | V28: ON PROSES ( PENGUAT PIGMENT) | X28: #REF!
A29: 13 | B29: CK | C29: SUPER PRINT RT - 88 | D29: KG | E29: 60 | F29: 0 | G29: 0 | H29: 60 | I29: 61766 | J29: 6794.26 | K29: 68560.26 | L29: 3705960 | M29: 4113615.6 | N29: 0 | O29: 0 | P29: 4113615.6 | Q29: 0 | R29: 0 | S29: 60 | T29: 0 | U29: CK | V29: ON PROSES | X29: #REF!
A30: 14 | B30: CK | C30: SUPER RUN PD - 1 ( SYNTETIC THICKENER ) | D30: KG | E30: 0 | F30: 2040 | G30: 0 | H30: 2040 | I30: 22728 | J30: 2500.08 | K30: 25228.08 | L30: 46365120 | M30: 0 | N30: 51465283 | O30: 0 | P30: 51465283 | Q30: 0 | R30: 0 | S30: 2040 | T30: 0 | U30: CK | V30: ON PROSES | X30: #REF!
A31: 14 | B31: CK | C31: THAXAPLAST DOP 100 (SOFTENER PASTA) | D31: KG | E31: 270 | F31: 0 | G31: 70 | H31: 200 | I31: 28000 | J31: 3080 | K31: 31080 | L31: 5600000 | M31: 8391600 | N31: 0 | O31: 2175600 | P31: 6216000 | Q31: 70 | R31: 0 | S31: 200 | T31: 70 | U31: CK | V31: RFP (CLP LORENG) / RFP (BLEACHING, KAIN TERTENTU) | X31: #REF! | Y31: #REF!
A32: 15 | B32: CK | C32: THICKENER P8E | D32: KG | E32: 180 | F32: 0 | G32: 120 | H32: 60 | I32: 55284 | J32: 6081.24 | K32: 61365.24 | L32: 3317040 | M32: 11045743 | N32: 0 | O32: 7363828.8 | P32: 3681914.4 | Q32: 120 | R32: 0 | S32: 60 | T32: 120 | U32: CK | V32: ON PROSES ( PENGUAT PIGMENT) | X32: #REF! | Y32: #REF!
A33: 16 | B33: CK | C33: ULTRAGUM HT 8 | D33: KG | E33: 4150 | F33: 0 | G33: 525 | H33: 3625 | I33: 21870 | J33: 2405.7 | K33: 24275.7 | L33: 79278750 | M33: 100744155 | N33: 0 | O33: 12744742 | P33: 87999412 | Q33: 525 | R33: 0 | S33: 3625 | T33: 525 | U33: CK | V33: ON PROSES | X33: #REF! | Y33: #REF!
A34: 17 | B34: CK | C34: THAXAPRINT EPX 7277 | D34: KG | E34: 0 | F34: 0 | G34: 0 | H34: 0 | I34: 22788 | J34: 2506.68 | K34: 25294.68 | L34: 0 | M34: 0 | N34: 0 | O34: 0 | P34: 0 | Q34: 0 | R34: 0 | S34: 0 | T34: 0 | U34: CK | V34: ON PROSES | X34: #REF! | Y34: #REF!
E35: 10278 | F35: 5420 | G35: 6306.5 | H35: 9392 | L35: 2.249687e+08 | M35: 2.7771575e+08 | N35: 1.3868378e+08 | O35: 1.6681004e+08 | P35: 2.4971526e+08 | X35: #REF!
X36: #REF!
A37: 1 | B37: DYEING | C37: BLANCOR GL | D37: KG | E37: 155 | F37: 0 | G37: 65 | H37: 90 | I37: 29502 | J37: 3245.22 | K37: 32747.22 | L37: 2655180 | M37: 5075819.1 | N37: 0 | O37: 2128569.3 | P37: 2947249.8 | Q37: 65 | R37: 0 | S37: 90 | T37: 65 | U37: DYEING | V37: RFP (CLP LORENG) | X37: #REF! | Y37: #REF!
A38: 2 | B38: DYEING | C38: DISPERSE BLUE ACE (LONGPERSE) | D38: KG | E38: 66.61 | F38: 0 | G38: 14.368 | H38: 53.88 | I38: 441045 | J38: 48514.95 | K38: 489559.95 | L38: 23763505 | M38: 32609588 | N38: 0 | O38: 7033997.4 | P38: 26377490 | Q38: 12.73 | R38: -1.638 | S38: 52.242 | T38: 14.368 | U38: DYEING | V38: RFP (CELUP LORENG) | X38: #REF!
A39: 3 | B39: DYEING | C39: DISPERSE RED ACE (LONGPERSE) | D39: KG | E39: 62.63 | F39: 0 | G39: 8.842 | H39: 54.06 | I39: 294030 | J39: 32343.3 | K39: 326373.3 | L39: 15895262 | M39: 20440760 | N39: 0 | O39: 2885792.7 | P39: 17643741 | Q39: 8.57 | R39: -0.272 | S39: 53.788 | T39: 8.842 | U39: DYEING | V39: RFP (CELUP LORENG) | X39: #REF!
A40: 4 | B40: DYEING | C40: DISPERSE YELLOW ACE (LONGPERSE) | D40: KG | E40: 63.63 | F40: 0 | G40: 16.79 | H40: 46.94 | I40: 262320 | J40: 28855.2 | K40: 291175.2 | L40: 12313301 | M40: 18527478 | N40: 0 | O40: 4888831.6 | P40: 13667764 | Q40: 16.69 | R40: -0.1 | S40: 46.84 | T40: 16.79 | U40: DYEING | V40: RFP (CELUP LORENG) | X40: #REF! | Y40: #REF!
A41: 5 | B41: DYEING | C41: DYAPOL N - 10 ( SABUN ) | D41: KG | E41: 0 | F41: 0 | G41: 0 | H41: 0 | I41: 7577.1 | J41: 833.481 | K41: 8410.581 | L41: 0 | M41: 0 | N41: 0 | O41: 0 | P41: 0 | Q41: 0 | R41: 0 | S41: 0 | T41: 0 | U41: DYEING | X41: #REF!
...

Sheet CHEMICAL
A1: PT. HERO SEKAWAN -
A2: DAFTAR TRANSAKSI M/K STOK
A3: PERIODE : | C3: 01-08-2025 s/d 31-08-2025
A4: JENIS BARANG: | C4: All | O4: NON | P4: +PPN | Q4: =SUBTOTAL(9,Q6:Q755) -> 29764.323 | T4: =SUBTOTAL(9,T6:T755) -> 6.3119469e+08 | U4: =SUBTOTAL(9,U6:U755) -> 6.993512e+08
A5: NOBUKTI | B5: TANGGAL | C5: JENIS BARANG | D5: KDTRAN | E5: MK | F5: GD | G5: KETERANGAN | H5: Stat | I5: NOURUT | J5: KDBRG | K5: NAMABRG | L5: KETERANGAN | M5: STNJ2 | N5: ISI3 | O5: HRGBELI | P5: HRGBELI | Q5: QTY | R5: qBESAR | S5: qKECIL | T5: TOTAL | U5: TOTAL + PPN | W5: 1000
A6: ST0825-00001 | B6: 2025-08-01 | C6: OBAT | D6: LM | E6: M | F6: Dyeing (06) | G6: FINISHING | H6: 0 | I6: 13 | J6: CHMA001 | K6: ACETIC ACID | L6: Kg | M6: Gr | N6: 1000 | O6: =SUMIF('GUDANG BESAR'!C:C,K:K,'GUDANG BESAR'!I:I) -> 13000 | P6: =SUMIF('GUDANG BESAR'!C:C,K:K,'GUDANG BESAR'!K:K) -> 14430 | Q6: 2 | R6: 2 | S6: 0 | T6: =O6*Q6 -> 26000 | U6: =P6*Q6 -> 28860 | V6: =VLOOKUP(K6,Sheet1!$B$5:$C$131,2,0) -> FINISHING | W6: =Q6/$W$5 -> 0.002
A7: ST0825-00001 | B7: 2025-08-01 | C7: OBAT | D7: LM | E7: M | F7: Limbah (14) | G7: LIMBAH | H7: 0 | I7: 23 | J7: CHMA0103 | K7: ANTIFOAM | L7: kg | M7: Gr | N7: 1000 | O7: =SUMIF('GUDANG BESAR'!C:C,K:K,'GUDANG BESAR'!I:I) -> 26000 | P7: =SUMIF('GUDANG BESAR'!C:C,K:K,'GUDANG BESAR'!K:K) -> 28860 | Q7: 30 | R7: 30 | S7: 0 | T7: =O7*Q7 -> 780000 | U7: =P7*Q7 -> 865800 | V7: =VLOOKUP(K7,Sheet1!$B$5:$C$131,2,0) -> LIMBAH | W7: =Q7/$W$5 -> 0.03
A8: ST0825-00001 | B8: 2025-08-01 | C8: OBAT | D8: LM | E8: M | F8: Dyeing (06) | G8: RC | H8: 0 | I8: 9 | J8: CHMA004 | K8: AVODA RC (THIOUREA DIOXIDE) | L8: Kg | M8: Gr | N8: 1000 | O8: =SUMIF('GUDANG BESAR'!C:C,K:K,'GUDANG BESAR'!I:I) -> 28844 | P8: =SUMIF('GUDANG BESAR'!C:C,K:K,'GUDANG BESAR'!K:K) -> 32016.84 | Q8: 50 | R8: 50 | S8: 0 | T8: =O8*Q8 -> 1442200 | U8: =P8*Q8 -> 1600842 | V8: =VLOOKUP(K8,Sheet1!$B$5:$C$131,2,0) -> RC | W8: =Q8/$W$5 -> 0.05
A9: ST0825-00001 | B9: 2025-08-01 | C9: OBAT | D9: LM | E9: M | F9: Dyeing (06) | G9: DYEING | H9: 0 | I9: 16 | J9: CHMB014 | K9: BLANCOR GL | L9: Kg | M9: Gr | N9: 1000 | O9: =SUMIF('GUDANG BESAR'!C:C,K:K,'GUDANG BESAR'!I:I) -> 29502 | P9: =SUMIF('GUDANG BESAR'!C:C,K:K,'GUDANG BESAR'!K:K) -> 32747.22 | Q9: 4 | R9: 4 | S9: 0 | T9: =O9*Q9 -> 118008 | U9: =P9*Q9 -> 130988.88 | V9: =VLOOKUP(K9,Sheet1!$B$5:$C$131,2,0) -> DYEING | W9: =Q9/$W$5 -> 0.004
A10: ST0825-00001 | B10: 2025-08-01 | C10: OBAT | D10: LM | E10: M | F10: Colour Kitchen (02) | G10: CK | H10: 0 | I10: 5 | J10: CHMC013 | K10: CITRIC ACID MONOHYDRATE | L10: Kg | M10: Gr | N10: 1000 | O10: =SUMIF('GUDANG BESAR'!C:C,K:K,'GUDANG BESAR'!I:I) -> 12250 | P10: =SUMIF('GUDANG BESAR'!C:C,K:K,'GUDANG BESAR'!K:K) -> 13597.5 | Q10: 2.5 | R10: 2 | S10: 500 | T10: =O10*Q10 -> 30625 | U10: =P10*Q10 -> 33993.75 | V10: =VLOOKUP(K10,Sheet1!$B$5:$C$131,2,0) -> CK | W10: =Q10/$W$5 -> 0.0025
A11: ST0825-00001 | B11: 2025-08-01 | C11: OBAT | D11: LM | E11: M | F11: Dyeing (06) | G11: RC | H11: 0 | I11: 10 | J11: CHMC014 | K11: COUSTIC SODA FLAKE | L11: Kg | M11: Gr | N11: 1000 | O11: =SUMIF('GUDANG BESAR'!C:C,K:K,'GUDANG BESAR'!I:I) -> 11087.5 | P11: =SUMIF('GUDANG BESAR'!C:C,K:K,'GUDANG BESAR'!K:K) -> 12307.125 | Q11: 50 | R11: 50 | S11: 0 | T11: =O11*Q11 -> 554375 | U11: =P11*Q11 -> 615356.25 | V11: =VLOOKUP(K11,Sheet1!$B$5:$C$131,2,0) -> RC | W11: =Q11/$W$5 -> 0.05
A12: ST0825-00001 | B12: 2025-08-01 | C12: OBAT | D12: LM | E12: M | F12: Dyeing (06) | G12: DYEING | H12: 0 | I12: 14 | J12: CHMD0119 | K12: DISPERSE BLUE ACE (LONGPERSE) | L12: Kg | M12: Gr | N12: 1000 | O12: =SUMIF('GUDANG BESAR'!C:C,K:K,'GUDANG BESAR'!I:I) -> 441045 | P12: =SUMIF('GUDANG BESAR'!C:C,K:K,'GUDANG BESAR'!K:K) -> 489559.95 | Q12: 0.5 | R12: 0 | S12: 500 | T12: =O12*Q12 -> 220522.5 | U12: =P12*Q12 -> 244779.98 | V12: =VLOOKUP(K12,Sheet1!$B$5:$C$131,2,0) -> DYEING | W12: =Q12/$W$5 -> 0.0005
A13: ST0825-00001 | B13: 2025-08-01 | C13: OBAT | D13: LM | E13: M | F13: Colour Kitchen (02) | G13: DYESTUFF | H13: 0 | I13: 1 | J13: CHMD023 | K13: DISPERSE BLUE SE 2R ( UNICRON ) | L13: Kg | M13: Gr | N13: 1000 | O13: =SUMIF('GUDANG BESAR'!C:C,K:K,'GUDANG BESAR'!I:I) -> 60680 | P13: =SUMIF('GUDANG BESAR'!C:C,K:K,'GUDANG BESAR'!K:K) -> 67354.8 | Q13: 24.525 | R13: 24 | S13: 525 | T13: =O13*Q13 -> 1488177 | U13: =P13*Q13 -> 1651876.5 | V13: =VLOOKUP(K13,Sheet1!$B$5:$C$131,2,0) -> DYESTUFF | W13: =Q13/$W$5 -> 0.024525
A14: ST0825-00001 | B14: 2025-08-01 | C14: OBAT | D14: LM | E14: M | F14: Colour Kitchen (02) | G14: DYESTUFF | H14: 0 | I14: 2 | J14: CHMD088 | K14: DISPERSE RED FFG | L14: Kg | M14: Gr | N14: 1000 | O14: =SUMIF('GUDANG BESAR'!C:C,K:K,'GUDANG BESAR'!I:I) -> 270075 | P14: =SUMIF('GUDANG BESAR'!C:C,K:K,'GUDANG BESAR'!K:K) -> 299783.25 | Q14: 0.66 | R14: 0 | S14: 660 | T14: =O14*Q14 -> 178249.5 | U14: =P14*Q14 -> 197856.95 | V14: =VLOOKUP(K14,Sheet1!$B$5:$C$131,2,0) -> DYESTUFF | W14: =Q14/$W$5 -> 0.00066
A15: ST0825-00001 | B15: 2025-08-01 | C15: OBAT | D15: LM | E15: M | F15: Colour Kitchen (02) | G15: DYESTUFF | H15: 0 | I15: 3 | J15: CHMD033 | K15: DISPERSE RUBINE S2GFL ( UNICRON ) | L15: Kg | M15: Gr | N15: 1000 | O15: =SUMIF('GUDANG BESAR'!C:C,K:K,'GUDANG BESAR'!I:I) -> 100812 | P15: =SUMIF('GUDANG BESAR'!C:C,K:K,'GUDANG BESAR'!K:K) -> 111901.32 | Q15: 2.236 | R15: 2 | S15: 236 | T15: =O15*Q15 -> 225415.63 | U15: =P15*Q15 -> 250211.35 | V15: =VLOOKUP(K15,Sheet1!$B$5:$C$131,2,0) -> DYESTUFF | W15: =Q15/$W$5 -> 0.002236
A16: ST0825-00001 | B16: 2025-08-01 | C16: OBAT | D16: LM | E16: M | F16: Colour Kitchen (02) | G16: DYESTUFF | H16: 0 | I16: 4 | J16: CHMD038 | K16: DISPERSE SCARLET 2R ( UNICRON ) | L16: Kg | M16: Gr | N16: 1000 | O16: =SUMIF('GUDANG BESAR'!C:C,K:K,'GUDANG BESAR'!I:I) -> 54071 | P16: =SUMIF('GUDANG BESAR'!C:C,K:K,'GUDANG BESAR'!K:K) -> 60018.81 | Q16: 3.675 | R16: 3 | S16: 675 | T16: =O16*Q16 -> 198710.92 | U16: =P16*Q16 -> 220569.13 | V16: =VLOOKUP(K16,Sheet1!$B$5:$C$131,2,0) -> DYESTUFF | W16: =Q16/$W$5 -> 0.003675
A17: ST0825-00001 | B17: 2025-08-01 | C17: OBAT | D17: LM | E17: M | F17: Dyeing (06) | G17: DYEING | H17: 0 | I17: 15 | J17: CHMD0117 | K17: DISPERSE YELLOW ACE (LONGPERSE) | L17: Kg | M17: Gr | N17: 1000 | O17: =SUMIF('GUDANG BESAR'!C:C,K:K,'GUDANG BESAR'!I:I) -> 262320 | P17: =SUMIF('GUDANG BESAR'!C:C,K:K,'GUDANG BESAR'!K:K) -> 291175.2 | Q17: 3.976 | R17: 3 | S17: 976 | T17: =O17*Q17 -> 1042984.3 | U17: =P17*Q17 -> 1157712.6 | V17: =VLOOKUP(K17,Sheet1!$B$5:$C$131,2,0) -> DYEING | W17: =Q17/$W$5 -> 0.003976
... A300: ST0825-00022 | B300: 2025-08-13 | C300: OBAT | D300: LM | E300: M | F300: Colour Kitchen (02) | G300: DYESTUFF | H300: 0 | I300: 6 | J300: CHMD0051 | K300: DISPERSE ORANGE 2GF 200% | L300: Kg | M300: Gr | N300: 1000 | O300: =SUMIF('GUDANG BESAR'!C:C,K:K,'GUDANG BESAR'!I:I) -> 71148 | P300: =SUMIF('GUDANG BESAR'!C:C,K:K,'GUDANG BESAR'!K:K) -> 78974.28 | Q300: 5.143 | R300: 5 | S300: 143 | T300: =O300*Q300 -> 365914.16 | U300: =P300*Q300 -> 406164.72 | V300: =VLOOKUP(K300,Sheet1!$B$5:$C$131,2,0) -> DYESTUFF | W300: =Q300/$W$5 -> 0.005143
A301: ST0825-00022 | B301: 2025-08-13 | C301: OBAT | D301: LM | E301: M | F301: Colour Kitchen (02) | G301: #N/A | H301: 0 | I301: 8 | J301: CHMD069 | K301: DISPERSE RED BEL | L301: Kg | M301: Gr | N301: 1000 | O301: =SUMIF('GUDANG BESAR'!C:C,K:K,'GUDANG BESAR'!I:I) -> 0 | P301: =SUMIF('GUDANG BESAR'!C:C,K:K,'GUDANG BESAR'!K:K) -> 0 | Q301: 0.082 | R301: 0 | S301: 82 | T301: =O301*Q301 -> 0 | U301: =P301*Q301 -> 0 | V301: =VLOOKUP(K301,Sheet1!$B$5:$C$131,2,0) -> #N/A | W301: =Q301/$W$5 -> 8.2e-05
A302: ST0825-00022 | B302: 2025-08-13 | C302: OBAT | D302: LM | E302: M | F302: Colour Kitchen (02) | G302: DYESTUFF | H302: 0 | I302: 9 | J302: CHMD080 | K302: DISPERSE RED F3BS 150% | L302: Kg | M302: Gr | N302: 1000 | O302: =SUMIF('GUDANG BESAR'!C:C,K:K,'GUDANG BESAR'!I:I) -> 385283 | P302: =SUMIF('GUDANG BESAR'!C:C,K:K,'GUDANG BESAR'!K:K) -> 427664.13 | Q302: 0.013 | R302: 0 | S302: 13 | T302: =O302*Q302 -> 5008.679 | U302: =P302*Q302 -> 5559.6337 | V302: =VLOOKUP(K302,Sheet1!$B$5:$C$131,2,0) -> DYESTUFF | W302: =Q302/$W$5 -> 1.3e-05
A303: ST0825-00022 | B303: 2025-08-13 | C303: OBAT | D303: LM | E303: M | F303: Colour Kitchen (02) | G303: DYESTUFF | H303: 0 | I303: 7 | J303: CHMD088 | K303: DISPERSE RED FFG | L303: Kg | M303: Gr | N303: 1000 | O303: =SUMIF('GUDANG BESAR'!C:C,K:K,'GUDANG BESAR'!I:I) -> 270075 | P303: =SUMIF('GUDANG BESAR'!C:C,K:K,'GUDANG BESAR'!K:K) -> 299783.25 | Q303: 0.022 | R303: 0 | S303: 22 | T303: =O303*Q303 -> 5941.65 | U303: =P303*Q303 -> 6595.2315 | V303: =VLOOKUP(K303,Sheet1!$B$5:$C$131,2,0) -> DYESTUFF | W303: =Q303/$W$5 -> 2.2e-05
A304: ST0825-00022 | B304: 2025-08-13 | C304: OBAT | D304: LM | E304: M | F304: Colour Kitchen (02) | G304: DYESTUFF | H304: 0 | I304: 10 | J304: CHMD033 | K304: DISPERSE RUBINE S2GFL ( UNICRON ) | L304: Kg | M304: Gr | N304: 1000 | O304: =SUMIF('GUDANG BESAR'!C:C,K:K,'GUDANG BESAR'!I:I) -> 100812 | P304: =SUMIF('GUDANG BESAR'!C:C,K:K,'GUDANG BESAR'!K:K) -> 111901.32 | Q304: 4.908 | R304: 4 | S304: 908 | T304: =O304*Q304 -> 494785.3 | U304: =P304*Q304 -> 549211.68 | V304: =VLOOKUP(K304,Sheet1!$B$5:$C$131,2,0) -> DYESTUFF | W304: =Q304/$W$5 -> 0.004908
A305: ST0825-00022 | B305: 2025-08-13 | C305: OBAT | D305: LM | E305: M | F305: Colour Kitchen (02) | G305: DYESTUFF | H305: 0 | I305: 11 | J305: CHMD038 | K305: DISPERSE SCARLET 2R ( UNICRON ) | L305: Kg | M305: Gr | N305: 1000 | O305: =SUMIF('GUDANG BESAR'!C:C,K:K,'GUDANG BESAR'!I:I) -> 54071 | P305: =SUMIF('GUDANG BESAR'!C:C,K:K,'GUDANG BESAR'!K:K) -> 60018.81 | Q305: 16.924 | R305: 16 | S305: 924 | T305: =O305*Q305 -> 915097.6 | U305: =P305*Q305 -> 1015758.3 | V305: =VLOOKUP(K305,Sheet1!$B$5:$C$131,2,0) -> DYESTUFF | W305: =Q305/$W$5 -> 0.016924
A306: ST0825-00022 | B306: 2025-08-13 | C306: OBAT | D306: LM | E306: M | F306: Colour Kitchen (02) | G306: DYESTUFF | H306: 0 | I306: 13 | J306: CHMD061 | K306: DISPERSE YELLOW 114 ECON ( 6 GSL ) | L306: Kg | M306: Gr | N306: 1000 | O306: =SUMIF('GUDANG BESAR'!C:C,K:K,'GUDANG BESAR'!I:I) -> 77089.4 | P306: =SUMIF('GUDANG BESAR'!C:C,K:K,'GUDANG BESAR'!K:K) -> 85569.234 | Q306: 17.005 | R306: 17 | S306: 5 | T306: =O306*Q306 -> 1310905.2 | U306: =P306*Q306 -> 1455104.8 | V306: =VLOOKUP(K306,Sheet1!$B$5:$C$131,2,0) -> DYESTUFF | W306: =Q306/$W$5 -> 0.017005
A307: ST0825-00022 | B307: 2025-08-13 | C307: OBAT | D307: LM | E307: M | F307: Colour Kitchen (02) | G307: CK | H307: 0 | I307: 14 | J307: CHML072 | K307: LEOPRINT 700 ( SYNTETIC THICKENER ) | L307: Kg | M307: Gr | N307: 1000 | O307: =SUMIF('GUDANG BESAR'!C:C,K:K,'GUDANG BESAR'!I:I) -> 23590.51 | P307: =SUMIF('GUDANG BESAR'!C:C,K:K,'GUDANG BESAR'!K:K) -> 26185.466 | Q307: 300 | R307: 300 | S307: 0 | T307: =O307*Q307 -> 7077153 | U307: =P307*Q307 -> 7855639.8 | V307: =VLOOKUP(K307,Sheet1!$B$5:$C$131,2,0) -> CK | W307: =Q307/$W$5 -> 0.3
A308: ST0825-00022 | B308: 2025-08-13 | C308: OBAT | D308: LM | E308: M | F308: Limbah (14) | G308: LIMBAH | H308: 0 | I308: 15 | J308: CHMP108 | K308: PAC PCO | L308: Kg | M308: Gr | N308: 1000 | O308: =SUMIF('GUDANG BESAR'!C:C,K:K,'GUDANG BESAR'!I:I) -> 5500 | P308: =SUMIF('GUDANG BESAR'!C:C,K:K,'GUDANG BESAR'!K:K) -> 6105 | Q308: 50 | R308: 50 | S308: 0 | T308: =O308*Q308 -> 275000 | U308: =P308*Q308 -> 305250 | V308: =VLOOKUP(K308,Sheet1!$B$5:$C$131,2,0) -> LIMBAH | W308: =Q308/$W$5 -> 0.05
A309: ST0825-00022 | B309: 2025-08-13 | C309: OBAT | D309: LM | E309: M | F309: Limbah (14) | G309: LIMBAH | H309: 0 | I309: 19 | J309: CHMU115 | K309: ULTRA BIOTIFIX | L309: Kg | M309: Gr | N309: 1000 | O309: =SUMIF('GUDANG BESAR'!C:C,K:K,'GUDANG BESAR'!I:I) -> 1550000 | P309: =SUMIF('GUDANG BESAR'!C:C,K:K,'GUDANG BESAR'!K:K) -> 1720500 | Q309: 0.05 | R309: 0 | S309: 50 | T309: =O309*Q309 -> 77500 | U309: =P309*Q309 -> 86025 | V309: =VLOOKUP(K309,Sheet1!$B$5:$C$131,2,0) -> LIMBAH | W309: =Q309/$W$5 -> 5e-05
A310: ST0825-00022 | B310: 2025-08-13 | C310: OBAT | D310: LM | E310: M | F310: Limbah (14) | G310: LIMBAH | H310: 0 | I310: 18 | J310: CHMU112 | K310: ULTRA NUTRI BIO S | L310: KG | M310: Gr | N310: 1000 | O310: =SUMIF('GUDANG BESAR'!C:C,K:K,'GUDANG BESAR'!I:I) -> 13180 | P310: =SUMIF('GUDANG BESAR'!C:C,K:K,'GUDANG BESAR'!K:K) -> 14629.8 | Q310: 15 | R310: 15 | S310: 0 | T310: =O310*Q310 -> 197700 | U310: =P310*Q310 -> 219447 | V310: =VLOOKUP(K310,Sheet1!$B$5:$C$131,2,0) -> LIMBAH | W310: =Q310/$W$5 -> 0.015
A311: ST0825-00022 | B311: 2025-08-13 | C311: OBAT | D311: LM | E311: M | F311: Limbah (14) | G311: LIMBAH | H311: 0 | I311: 16 | J311: CHMW0005 | K311: WPA 5205 ( POLYMER ANIONIC) | L311: Kg | M311: Gr | N311: 1000 | O311: =SUMIF('GUDANG BESAR'!C:C,K:K,'GUDANG BESAR'!I:I) -> 33000 | P311: =SUMIF('GUDANG BESAR'!C:C,K:K,'GUDANG BESAR'!K:K) -> 36630 | Q311: 2 | R311: 2 | S311: 0 | T311: =O311*Q311 -> 66000 | U311: =P311*Q311 -> 73260 | V311: =VLOOKUP(K311,Sheet1!$B$5:$C$131,2,0) -> LIMBAH | W311: =Q311/$W$5 -> 0.002
A312: ST0825-00022 | B312: 2025-08-13 | C312: OBAT | D312: LM | E312: M | F312: Limbah (14) | G312: LIMBAH | H312: 0 | I312: 17 | J312: CHMW0001 | K312: WPC - 2967 ( POLYMER CATHIONIC ) | L312: Kg | M312: Gr | N312: 1000 | O312: =SUMIF('GUDANG BESAR'!C:C,K:K,'GUDANG BESAR'!I:I) -> 47500 | P312: =SUMIF('GUDANG BESAR'!C:C,K:K,'GUDANG BESAR'!K:K) -> 52725 | Q312: 2 | R312: 2 | S312: 0 | T312: =O312*Q312 -> 95000 | U312: =P312*Q312 -> 105450 | V312: =VLOOKUP(K312,Sheet1!$B$5:$C$131,2,0) -> LIMBAH | W312: =Q312/$W$5 -> 0.002
A313: ST0825-00024 | B313: 2025-08-14 | C313: OBAT | D313: LM | E313: M | F313: Dyeing (06) | G313: FINISHING | H313: 0 | I313: 17 | J313: CHMA001 | K313: ACETIC ACID | L313: Kg | M313: Gr | N313: 1000 | O313: =SUMIF('GUDANG BESAR'!C:C,K:K,'GUDANG BESAR'!I:I) -> 13000 | P313: =SUMIF('GUDANG BESAR'!C:C,K:K,'GUDANG BESAR'!K:K) -> 14430 | Q313: 8 | R313: 8 | S313: 0 | T313: =O313*Q313 -> 104000 | U313: =P313*Q313 -> 115440 | V313: =VLOOKUP(K313,Sheet1!$B$5:$C$131,2,0) -> FINISHING | W313: =Q313/$W$5 -> 0.008
... A385: ST0825-00028 | B385: 2025-08-16 | C385: OBAT | D385: LM | E385: M | F385: Colour Kitchen (02) | G385: DYESTUFF | H385: 0 | I385: 7 | J385: CHMD0051 | K385: DISPERSE ORANGE 2GF 200% | L385: Kg | M385: Gr | N385: 1000 | O385: =SUMIF('GUDANG BESAR'!C:C,K:K,'GUDANG BESAR'!I:I) -> 71148 | P385: =SUMIF('GUDANG BESAR'!C:C,K:K,'GUDANG BESAR'!K:K) -> 78974.28 | Q385: 2.814 | R385: 2 | S385: 814 | T385: =O385*Q385 -> 200210.47 | U385: =P385*Q385 -> 222233.62 | V385: =VLOOKUP(K385,Sheet1!$B$5:$C$131,2,0) -> DYESTUFF | W385: =Q385/$W$5 -> 0.002814
A386: ST0825-00028 | B386: 2025-08-16 | C386: OBAT | D386: LM | E386: M | F386: Colour Kitchen (02) | G386: #N/A | H386: 0 | I386: 8 | J386: CHMD069 | K386: DISPERSE RED BEL | L386: Kg | M386: Gr | N386: 1000 | O386: =SUMIF('GUDANG BESAR'!C:C,K:K,'GUDANG BESAR'!I:I) -> 0 | P386: =SUMIF('GUDANG BESAR'!C:C,K:K,'GUDANG BESAR'!K:K) -> 0 | Q386: 0.018 | R386: 0 | S386: 18 | T386: =O386*Q386 -> 0 | U386: =P386*Q386 -> 0 | V386: =VLOOKUP(K386,Sheet1!$B$5:$C$131,2,0) -> #N/A | W386: =Q386/$W$5 -> 1.8e-05
A387: ST0825-00028 | B387: 2025-08-16 | C387: OBAT | D387: LM | E387: M | F387: Colour Kitchen (02) | G387: DYESTUFF | H387: 0 | I387: 9 | J387: CHMD080 | K387: DISPERSE RED F3BS 150% | L387: Kg | M387: Gr | N387: 1000 | O387: =SUMIF('GUDANG BESAR'!C:C,K:K,'GUDANG BESAR'!I:I) -> 385283 | P387: =SUMIF('GUDANG BESAR'!C:C,K:K,'GUDANG BESAR'!K:K) -> 427664.13 | Q387: 0.009 | R387: 0 | S387: 9 | T387: =O387*Q387 -> 3467.547 | U387: =P387*Q387 -> 3848.9772 | V387: =VLOOKUP(K387,Sheet1!$B$5:$C$131,2,0) -> DYESTUFF | W387: =Q387/$W$5 -> 9e-06
A388: ST0825-00028 | B388: 2025-08-16 | C388: OBAT | D388: LM | E388: M | F388: Colour Kitchen (02) | G388: DYESTUFF | H388: 0 | I388: 10 | J388: CHMD033 | K388: DISPERSE RUBINE S2GFL ( UNICRON ) | L388: Kg | M388: Gr | N388: 1000 | O388: =SUMIF('GUDANG BESAR'!C:C,K:K,'GUDANG BESAR'!I:I) -> 100812 | P388: =SUMIF('GUDANG BESAR'!C:C,K:K,'GUDANG BESAR'!K:K) -> 111901.32 | Q388: 1.358 | R388: 1 | S388: 358 | T388: =O388*Q388 -> 136902.7 | U388: =P388*Q388 -> 151961.99 | V388: =VLOOKUP(K388,Sheet1!$B$5:$C$131,2,0) -> DYESTUFF | W388: =Q388/$W$5 -> 0.001358
A389: ST0825-00028 | B389: 2025-08-16 | C389: OBAT | D389: LM | E389: M | F389: Colour Kitchen (02) | G389: DYESTUFF | H389: 0 | I389: 11 | J389: CHMD038 | K389: DISPERSE SCARLET 2R ( UNICRON ) | L389: Kg | M389: Gr | N389: 1000 | O389: =SUMIF('GUDANG BESAR'!C:C,K:K,'GUDANG BESAR'!I:I) -> 54071 | P389: =SUMIF('GUDANG BESAR'!C:C,K:K,'GUDANG BESAR'!K:K) -> 60018.81 | Q389: 9.638 | R389: 9 | S389: 638 | T389: =O389*Q389 -> 521136.3 | U389: =P389*Q389 -> 578461.29 | V389: =VLOOKUP(K389,Sheet1!$B$5:$C$131,2,0) -> DYESTUFF | W389: =Q389/$W$5 -> 0.009638
A390: ST0825-00028 | B390: 2025-08-16 | C390: OBAT | D390: LM | E390: M | F390: Colour Kitchen (02) | G390: DYESTUFF | H390: 0 | I390: 13 | J390: CHMD103 | K390: DISPERSE VIOLET S3R (ATLACRON) | L390: Kg | M390: Gr | N390: 1000 | O390: =SUMIF('GUDANG BESAR'!C:C,K:K,'GUDANG BESAR'!I:I) -> 100590 | P390: =SUMIF('GUDANG BESAR'!C:C,K:K,'GUDANG BESAR'!K:K) -> 111654.9 | Q390: 0.006 | R390: 0 | S390: 6 | T390: =O390*Q390 -> 603.54 | U390: =P390*Q390 -> 669.9294 | V390: =VLOOKUP(K390,Sheet1!$B$5:$C$131,2,0) -> DYESTUFF | W390: =Q390/$W$5 -> 6e-06
A391: ST0825-00028 | B391: 2025-08-16 | C391: OBAT | D391: LM | E391: M | F391: Colour Kitchen (02) | G391: DYESTUFF | H391: 0 | I391: 14 | J391: CHMD061 | K391: DISPERSE YELLOW 114 ECON ( 6 GSL ) | L391: Kg | M391: Gr | N391: 1000 | O391: =SUMIF('GUDANG BESAR'!C:C,K:K,'GUDANG BESAR'!I:I) -> 77089.4 | P391: =SUMIF('GUDANG BESAR'!C:C,K:K,'GUDANG BESAR'!K:K) -> 85569.234 | Q391: 5.508 | R391: 5 | S391: 508 | T391: =O391*Q391 -> 424608.42 | U391: =P391*Q391 -> 471315.34 | V391: =VLOOKUP(K391,Sheet1!$B$5:$C$131,2,0) -> DYESTUFF | W391: =Q391/$W$5 -> 0.005508
A392: ST0825-00028 | B392: 2025-08-16 | C392: OBAT | D392: LM | E392: M | F392: Limbah (14) | G392: LIMBAH | H392: 0 | I392: 19 | J392: CHMD094 | K392: DK FOAM HT 42 S (ANTI FOAM) | L392: Kg | M392: Gr | N392: 1000 | O392: =SUMIF('GUDANG BESAR'!C:C,K:K,'GUDANG BESAR'!I:I) -> 30500 | P392: =SUMIF('GUDANG BESAR'!C:C,K:K,'GUDANG BESAR'!K:K) -> 33855 | Q392: 15 | R392: 15 | S392: 0 | T392: =O392*Q392 -> 457500 | U392: =P392*Q392 -> 507825 | V392: =VLOOKUP(K392,Sheet1!$B$5:$C$131,2,0) -> LIMBAH | W392: =Q392/$W$5 -> 0.015
A393: ST0825-00028 | B393: 2025-08-16 | C393: OBAT | D393: LM | E393: M | F393: Colour Kitchen (02) | G393: CK | H393: 0 | I393: 15 | J393: CHML072 | K393: LEOPRINT 700 ( SYNTETIC THICKENER ) | L393: Kg | M393: Gr | N393: 1000 | O393: =SUMIF('GUDANG BESAR'!C:C,K:K,'GUDANG BESAR'!I:I) -> 23590.51 | P393: =SUMIF('GUDANG BESAR'!C:C,K:K,'GUDANG BESAR'!K:K) -> 26185.466 | Q393: 180 | R393: 180 | S393: 0 | T393: =O393*Q393 -> 4246291.8 | U393: =P393*Q393 -> 4713383.9 | V393: =VLOOKUP(K393,Sheet1!$B$5:$C$131,2,0) -> CK | W393: =Q393/$W$5 -> 0.18
...

Sheet TARIK DATA
A1: PT. HERO SEKAWAN -
A2: DAFTAR TRANSAKSI M/K STOK
A3: PERIODE : | C3: 01-08-2025 s/d 31-08-2025
A4: JENIS BARANG: | C4: All
A5: NOBUKTI | B5: TANGGAL | C5: JENIS BARANG | D5: KDTRAN | E5: MK | F5: GD | G5: KETERANGAN | H5: Stat | I5: NOURUT | J5: KDBRG | K5: NAMABRG | L5: STNJ1 | M5: STNJ2 | N5: ISI3 | O5: HRGBELI | Q5: QTY | R5: qBESAR | S5: qKECIL
A6: ST0825-00001 | B6: 2025-08-01 | C6: OBAT | D6: LM | E6: M | F6: Colour Kitchen (02) | G6: CHEMICAL CUT OFF | H6: 0 | I6: 1 | J6: CHMD023 | K6: DISPERSE BLUE SE 2R ( UNICRON ) | L6: Kg | M6: Gr | N6: 1000 | O6: 0.001 | Q6: 24525 | R6: 24 | S6: 525
A7: ST0825-00001 | B7: 2025-08-01 | C7: OBAT | D7: LM | E7: M | F7: Colour Kitchen (02) | G7: CHEMICAL CUT OFF | H7: 0 | I7: 2 | J7: CHMD088 | K7: DISPERSE RED FFG | L7: Kg | M7: Gr | N7: 1000 | O7: 0.001 | Q7: 660 | R7: 0 | S7: 660
A8: ST0825-00001 | B8: 2025-08-01 | C8: OBAT | D8: LM | E8: M | F8: Colour Kitchen (02) | G8: CHEMICAL CUT OFF | H8: 0 | I8: 3 | J8: CHMD033 | K8: DISPERSE RUBINE S2GFL ( UNICRON ) | L8: Kg | M8: Gr | N8: 1000 | O8: 0.001 | Q8: 2236 | R8: 2 | S8: 236
A9: ST0825-00001 | B9: 2025-08-01 | C9: OBAT | D9: LM | E9: M | F9: Colour Kitchen (02) | G9: CHEMICAL CUT OFF | H9: 0 | I9: 4 | J9: CHMD038 | K9: DISPERSE SCARLET 2R ( UNICRON ) | L9: Kg | M9: Gr | N9: 1000 | O9: 0.001 | Q9: 3675 | R9: 3 | S9: 675
A10: ST0825-00001 | B10: 2025-08-01 | C10: OBAT | D10: LM | E10: M | F10: Colour Kitchen (02) | G10: CHEMICAL CUT OFF | H10: 0 | I10: 5 | J10: CHMC013 | K10: CITRIC ACID MONOHYDRATE | L10: Kg | M10: Gr | N10: 1000 | O10: 19 | Q10: 2500 | R10: 2 | S10: 500
A11: ST0825-00001 | B11: 2025-08-01 | C11: OBAT | D11: LM | E11: M | F11: Colour Kitchen (02) | G11: CHEMICAL CUT OFF | H11: 0 | I11: 6 | J11: CHMS096 | K11: SODIUM HEXA METHA POSPHAT POWDER (SHMP) | L11: Kg | M11: Gr | N11: 1000 | O11: 20.5 | Q11: 500 | R11: 0 | S11: 500
A12: ST0825-00001 | B12: 2025-08-01 | C12: OBAT | D12: LM | E12: M | F12: Colour Kitchen (02) | G12: CHEMICAL CUT OFF | H12: 0 | I12: 7 | J12: CHMU099 | K12: ULTRAGUM HT 8 | L12: Kg | M12: Gr | N12: 1000 | O12: 16 | Q12: 25000 | R12: 25 | S12: 0
A13: ST0825-00001 | B13: 2025-08-01 | C13: OBAT | D13: LM | E13: M | F13: Colour Kitchen (02) | G13: CHEMICAL CUT OFF | H13: 0 | I13: 8 | J13: CHML072 | K13: LEOPRINT 700 ( SYNTETIC THICKENER ) | L13: Kg | M13: Gr | N13: 1000 | O13: 0.001 | Q13: 180000 | R13: 180 | S13: 0
A14: ST0825-00001 | B14: 2025-08-01 | C14: OBAT | D14: LM | E14: M | F14: Dyeing (06) | G14: CHEMICAL CUT OFF | H14: 0 | I14: 9 | J14: CHMA004 | K14: AVODA RC (THIOUREA DIOXIDE) | L14: Kg | M14: Gr | N14: 1000 | O14: 32.021 | Q14: 50000 | R14: 50 | S14: 0
A15: ST0825-00001 | B15: 2025-08-01 | C15: OBAT | D15: LM | E15: M | F15: Dyeing (06) | G15: CHEMICAL CUT OFF | H15: 0 | I15: 10 | J15: CHMC014 | K15: COUSTIC SODA FLAKE | L15: Kg | M15: Gr | N15: 1000 | O15: 13.6 | Q15: 50000 | R15: 50 | S15: 0
A16: ST0825-00001 | B16: 2025-08-01 | C16: OBAT | D16: LM | E16: M | F16: Dyeing (06) | G16: CHEMICAL CUT OFF | H16: 0 | I16: 11 | J16: CHMS0125 | K16: SUPER SCOUR | L16: Kg | M16: Gr | N16: 1000 | O16: 0.001 | Q16: 5000 | R16: 5 | S16: 0
A17: ST0825-00001 | B17: 2025-08-01 | C17: OBAT | D17: LM | E17: M | F17: Dyeing (06) | G17: CHEMICAL CUT OFF | H17: 0 | I17: 12 | J17: CHMS119 | K17: SUNPERSE TS 37 | L17: Kg | M17: Gr | N17: 1000 | O17: 0.001 | Q17: 18000 | R17: 18 | S17: 0
... A1137: ST0825-00053 | B1137: 2025-08-30 | C1137: UMUM | D1137: LM | E1137: M | F1137: Limbah (14) | G1137: SPARE PART | H1137: 0 | I1137: 5 | J1137: UMK0033 | K1137: KARUNG BERAS 25 KG | L1137: PCS | M1137: PCS | N1137: 1 | O1137: 1 | Q1137: 300 | R1137: 300 | S1137: 0

Sheet Sheet2
B1: REKAP PEMAKAIAN CHEMICAL AGUSTUS 2025
C2: NON | D2: +PPN
B3: Boiler (13) | C3: =SUMIF(#REF!,Sheet2!B:B,#REF!) -> #REF! | D3: =SUMIF(CHEMICAL!F:F,Sheet2!B:B,CHEMICAL!U:U) -> 13870800
B4: Colour Kitchen (02) | C4: =SUMIF(#REF!,Sheet2!B:B,#REF!) -> #REF! | D4: =SUMIF(CHEMICAL!F:F,Sheet2!B:B,CHEMICAL!U:U) -> 3.2982809e+08
B5: Dyeing (06) | C5: =SUMIF(#REF!,Sheet2!B:B,#REF!) -> #REF! | D5: =SUMIF(CHEMICAL!F:F,Sheet2!B:B,CHEMICAL!U:U) -> 1.5849317e+08
B6: Gudang Enggrafing (16) | C6: =SUMIF(#REF!,Sheet2!B:B,#REF!) -> #REF! | D6: =SUMIF(CHEMICAL!F:F,Sheet2!B:B,CHEMICAL!U:U) -> 83720890
B7: Limbah (14) | C7: =SUMIF(#REF!,Sheet2!B:B,#REF!) -> #REF! | D7: =SUMIF(CHEMICAL!F:F,Sheet2!B:B,CHEMICAL!U:U) -> 105650355
B8: Printing (15) | C8: =SUMIF(#REF!,Sheet2!B:B,#REF!) -> #REF! | D8: =SUMIF(CHEMICAL!F:F,Sheet2!B:B,CHEMICAL!U:U) -> 3558393.6
B9: Stenter (07) | C9: =SUMIF(#REF!,Sheet2!B:B,#REF!) -> #REF! | D9: =SUMIF(CHEMICAL!F:F,Sheet2!B:B,CHEMICAL!U:U) -> 2826894.5
B10: Maintenance (12) | D10: =SUMIF(CHEMICAL!F:F,Sheet2!B:B,CHEMICAL!U:U) -> 0
B11: Gudang Umum (05) | D11: =SUMIF(CHEMICAL!F:F,Sheet2!B:B,CHEMICAL!U:U) -> 0
B12: Gudang Besar (00) | D12: =SUMIF(CHEMICAL!F:F,Sheet2!B:B,CHEMICAL!U:U) -> 1402608.2
C14: =SUM(C3:C13) -> #REF! | D14: =SUM(D3:D13) -> 6.993512e+08
B17: REKAP PEMAKAIAN CHEMICAL AGUSTUS 2025
C18: NON | D18: +PPN
B19: BOILER | C19: =SUMIF(#REF!,Sheet2!F:F,#REF!) -> #REF! | D19: =SUMIF(CHEMICAL!G:G,$B$19:$B$28,CHEMICAL!U:U) -> 13870800
B20: CK | C20: =SUMIF(#REF!,Sheet2!F:F,#REF!) -> #REF! | D20: =SUMIF(CHEMICAL!G:G,$B$19:$B$28,CHEMICAL!U:U) -> 1.6681004e+08
B21: DYEING | C21: =SUMIF(#REF!,Sheet2!F:F,#REF!) -> #REF! | D21: =SUMIF(CHEMICAL!G:G,$B$19:$B$28,CHEMICAL!U:U) -> 45505900
B22: DYESTUFF | C22: =SUMIF(#REF!,Sheet2!F:F,#REF!) -> #REF! | D22: =SUMIF(CHEMICAL!G:G,$B$19:$B$28,CHEMICAL!U:U) -> 1.6291999e+08
B23: ENGGRAVING | C23: =SUMIF(#REF!,Sheet2!F:F,#REF!) -> #REF! | D23: =SUMIF(CHEMICAL!G:G,$B$19:$B$28,CHEMICAL!U:U) -> 83761960
B24: FINISHING | C24: =SUMIF(#REF!,Sheet2!F:F,#REF!) -> #REF! | D24: =SUMIF(CHEMICAL!G:G,$B$19:$B$28,CHEMICAL!U:U) -> 2813421.5
B25: LIMBAH | C25: =SUMIF(#REF!,Sheet2!F:F,#REF!) -> #REF! | D25: =SUMIF(CHEMICAL!G:G,$B$19:$B$28,CHEMICAL!U:U) -> 105650355
B26: RC | D26: =SUMIF(CHEMICAL!G:G,$B$19:$B$28,CHEMICAL!U:U) -> 1.1290579e+08
B27: CHEMICAL PRINTING | D27: =SUMIF(CHEMICAL!G:G,$B$19:$B$28,CHEMICAL!U:U) -> 3517323.6
B28: CHEM.DYEING | D28: =SUMIF(CHEMICAL!G:G,$B$19:$B$28,CHEMICAL!U:U) -> 1595625
C30: =SUM(C19:C29) -> #REF! | D30: =SUM(D19:D29) -> 6.993512e+08
C32: =+#REF! -> #REF! | D32: =+CHEMICAL!U4 -> 6.993512e+08
C33: =C30-C32 -> #REF! | D33: =D30-D32 -> 0

Sheet Sheet1
C1: STOCK CHEMICAL
C3: GUDANG BESAR PER JULI 2025
B5: NAMA BARANG | C5: KETERANGAN
B6: CHEMPOWER - 1400 | C6: BOILER
B7: CHEMPOWER - 2002 | C7: BOILER
B8: GARAM KROGUS | C8: BOILER
B11: LEM GML PK (LEM BLANKET) | C11: CHEMICAL PRINTING
B12: RENOGENT | C12: CHEMICAL PRINTING
B13: THERMACOAT RESIN TO 90 | C13: CHEMICAL PRINTING
B16: ANTI UV - RUCO SHIELD RAY 500 | C16: CK
B17: ANTISTATIK SZ - 52 | C17: CK
B18: BINDER 660 N | C18: CK
B19: BINDER FN (HARD BINDER) | C19: CK
B20: BINDER SOFT TF - T 320 S | C20: CK
... B122: REDUCON RC - 02 | C122: RC
B125: TOTAL
B127: CATALIST HX
B128: DISPERSE BRILL BLUE SRP (CEMALON)
B129: DISPERSE NAVY BLUE 3G H7 C (KISPERSE)
B130: DISPERSE RED F3BS (SEMARON)
B131: DISPERSE RED S3BS (343)
B132: DISPERSE RUBINE S -2G 200% (DISPALON)
B133: DISPERSE VIOLET FBL ( VIOLET 26)
B134: DISPERSE YELLOW 10 G (184)
B135: DISPERSE YELLOW 10 GN 400%
B136: DIPSERSE RUBINE S2G ( RED 167)
B137: FX - 200 ( FIXER )
... B148: TOTAL
